<?xml version="1.0" encoding="UTF-8"?>
<!-- Generated by org.testng.reporters.JUnitReportReporter -->
<testsuite hostname="nikunj-20h1cto1ww" failures="0" tests="6" name="TestCalculate" time="0.027" errors="1" timestamp="2021-01-15T02:45:47 IST" skipped="0">
  <testcase classname="TestCalculate" name="ReturnSumofTwoNumberWithCommaDelimiter" time="0.002"/>
  <system-out/>
  <testcase classname="TestCalculate" name="StringWithnegativeNumberReturnsException" time="0.001">
    <error message="
Method TestCalculate.StringWithnegativeNumberReturnsException()[pri:0, instance:TestCalculate@6a2b953e] should have thrown an exception of type class java.lang.Exception" type="org.testng.TestException">
      <![CDATA[org.testng.TestException: 
Method TestCalculate.StringWithnegativeNumberReturnsException()[pri:0, instance:TestCalculate@6a2b953e] should have thrown an exception of type class java.lang.Exception
at org.testng.internal.ExpectedExceptionsHolder.noException(ExpectedExceptionsHolder.java:82)
at org.testng.internal.TestInvoker.considerExceptions(TestInvoker.java:747)
at org.testng.internal.TestInvoker.invokeMethod(TestInvoker.java:635)
at org.testng.internal.TestInvoker.invokeTestMethod(TestInvoker.java:174)
at org.testng.internal.MethodRunner.runInSequence(MethodRunner.java:46)
at org.testng.internal.TestInvoker$MethodInvocationAgent.invoke(TestInvoker.java:822)
at org.testng.internal.TestInvoker.invokeTestMethods(TestInvoker.java:147)
at org.testng.internal.TestMethodWorker.invokeTestMethods(TestMethodWorker.java:146)
at org.testng.internal.TestMethodWorker.run(TestMethodWorker.java:128)
at java.base/java.util.ArrayList.forEach(ArrayList.java:1511)
at org.testng.TestRunner.privateRun(TestRunner.java:764)
at org.testng.TestRunner.run(TestRunner.java:585)
at org.testng.SuiteRunner.runTest(SuiteRunner.java:384)
at org.testng.SuiteRunner.runSequentially(SuiteRunner.java:378)
at org.testng.SuiteRunner.privateRun(SuiteRunner.java:337)
at org.testng.SuiteRunner.run(SuiteRunner.java:286)
at org.testng.SuiteRunnerWorker.runSuite(SuiteRunnerWorker.java:53)
at org.testng.SuiteRunnerWorker.run(SuiteRunnerWorker.java:96)
at org.testng.TestNG.runSuitesSequentially(TestNG.java:1218)
at org.testng.TestNG.runSuitesLocally(TestNG.java:1140)
at org.testng.TestNG.runSuites(TestNG.java:1069)
at org.testng.TestNG.run(TestNG.java:1037)
at org.testng.remote.AbstractRemoteTestNG.run(AbstractRemoteTestNG.java:115)
at org.testng.remote.RemoteTestNG.initAndRun(RemoteTestNG.java:251)
at org.testng.remote.RemoteTestNG.main(RemoteTestNG.java:77)
]]>
    </error>
  </testcase> <!-- StringWithnegativeNumberReturnsException -->
  <system-out/>
  <testcase classname="TestCalculate" name="ReturnSumofThreeNumberWithCommaAndNewLineDelimiter" time="0.002"/>
  <system-out/>
  <testcase classname="TestCalculate" name="StringWithSingleNumber" time="0.002"/>
  <system-out/>
  <testcase classname="TestCalculate" name="EmptyStringReturnZero" time="0.019"/>
  <system-out/>
  <testcase classname="TestCalculate" name="ReturnSumofTwoNumberWithNewLineDelimiter" time="0.001"/>
  <system-out/>
</testsuite> <!-- TestCalculate -->
